Workbook

Sheet 📋 Master Plan
A1: 🎯 TECHNICAL INTERVIEW PREP — MASTER PLAN
A3: Target: 500+ Problems | Daily: 2 hrs DSA + 1 hr System Design | Total Duration: ~16 Weeks
A5: STUDY PHASES OVERVIEW
A6: Phase | B6: Weeks | C6: DSA Focus Area | D6: Key Concepts | E6: Problem Count Target | F6: System Design Topic | G6: Daily DSA Time | H6: Daily SD Time | I6: Difficulty Mix | J6: Cumulative Problems
A7: Phase 1 | B7: Wks 1–2 | C7: Foundations | D7: Arrays, Strings, Hashing, Two Pointers, Sliding Window | E7: 60 | F7: Scalability & Basics | G7: 90 min | H7: 30 min | I7: 80% Easy / 20% Med | J7: 60
A8: Phase 2 | B8: Wks 3–4 | C8: Linear Structures | D8: Linked Lists, Stacks, Queues, Monotonic Structures | E8: 60 | F8: Storage & Caching | G8: 90 min | H8: 30 min | I8: 60% Easy / 40% Med | J8: 120
A9: Phase 3 | B9: Wks 5–6 | C9: Trees & Graphs | D9: Binary Trees, BST, Tries, Graph BFS/DFS, Union-Find | E9: 80 | F9: Distributed Systems Intro | G9: 80 min | H9: 40 min | I9: 40% Easy / 50% Med / 10% Hard | J9: 200
A10: Phase 4 | B10: Wks 7–8 | C10: Recursion & DP | D10: Backtracking, 1D DP, 2D DP, Greedy | E10: 80 | F10: Design Deep Dives I | G10: 70 min | H10: 50 min | I10: 20% Easy / 60% Med / 20% Hard | J10: 280
A11: Phase 5 | B11: Wks 9–10 | C11: Advanced Algorithms | D11: Heaps, Advanced Graphs, Intervals, Bit Manipulation | E11: 70 | F11: Design Deep Dives II | G11: 60 min | H11: 60 min | I11: 10% Easy / 60% Med / 30% Hard | J11: 350
A12: Phase 6 | B12: Wks 11–12 | C12: Hard & Patterns | D12: Hard DP, Advanced Trees, Segment Trees, Math | E12: 60 | F12: Design Deep Dives III | G12: 60 min | H12: 60 min | I12: 5% Easy / 50% Med / 45% Hard | J12: 410
A13: Phase 7 | B13: Wks 13–14 | C13: Mock & Review | D13: Mixed company-tagged sets, timed contests | E13: 50 | F13: Full Mock System Designs | G13: 50 min | H13: 70 min | I13: Company-Specific Mix | J13: 460
A14: Phase 8 | B14: Wks 15–16 | C14: Final Sprint | D14: Weak-area revisit, top 75 NeetCode revisit | E14: 40 | F14: Behavioral + SD Combos | G14: 45 min | H14: 75 min | I14: Interview-Intensity | J14: 500+
A17: 📅 DAILY SCHEDULE TEMPLATE
A18: Time Block | B18: Duration | C18: Activity | D18: What To Do | E18: Notes
A19: Block 1 | B19: 30 min | C19: Warm-up / Review | D19: Re-read yesterday's notes, review 2–3 solved problems | E19: Active recall, not passive reading
A20: Block 2 | B20: 60 min | C20: New DSA Topic | D20: Study concept deeply → understand intuition → code from scratch | E20: No copy-paste; understand WHY
A21: Block 3 | B21: 30 min | C21: Practice Problems | D21: Solve 2–4 problems on current topic (timed: 20–25 min each) | E21: Track in Problem Log sheet
A22: Block 4 | B22: 60 min | C22: System Design | D22: Study 1 SD concept + design a system end-to-end with trade-offs | E22: Use the SD sheet as checklist
A23: Buffer | B23: — | C23: Spaced Repetition | D23: Flag hard problems for re-attempt in 3/7/14 days | E23: Use the Retry Tracker sheet

Sheet 🧠 DSA Topics & Problems
A1: 🧠 DSA TOPICS, KEY CONCEPTS & MUST-SOLVE PROBLEMS
A3: # | B3: Topic / Category | C3: Core Concepts to Understand | D3: Key Patterns & Techniques | E3: Must-Solve Problems (LeetCode) | F3: Difficulty | G3: # Problems | H3: Phase | I3: Concept Tags | J3: Notes / Tips | K3: Mastery Level
A4: 1 | B4: Arrays & Hashing | C4: Contiguous memory, index ops, hash maps for O(1) lookup, frequency counting | D4: Two-pass counting, complement lookup, prefix sum | E4: Two Sum (1), Contains Duplicate (217), Valid Anagram (242), Group Anagrams (49), Top K Frequent (347), Product of Array Except Self (238), Encode/Decode Strings (659), Longest Consecutive Sequence (128) | F4: E/M | G4: 8 | H4: Phase 1 | I4: Arrays, Hashing, Frequency | J4: Master HashMap before moving on | K4: ⬜ Not Started
A5: 2 | B5: Two Pointers | C5: Opposite-end pointers, same-direction pointers, fast/slow trick | D5: Sorted array scan, palindrome check, pair/triplet sums | E5: Valid Palindrome (125), Two Sum II (167), 3Sum (15), Container With Most Water (11), Trapping Rain Water (42) | F5: E/M/H | G5: 5 | H5: Phase 1 | I5: Two Pointers, Sorting | J5: Trapping Rain Water is a must-understand | K5: ⬜ Not Started
A6: 3 | B6: Sliding Window | C6: Fixed & variable window, window expansion/contraction, maintaining invariants | D6: Max/min subarray, distinct chars window, at-most-K variants | E6: Best Time to Buy & Sell Stock (121), Longest Substring Without Repeating (3), Longest Repeating Character Replacement (424), Permutation in String (567), Minimum Window Substring (76), Sliding Window Maximum (239) | F6: E/M/H | G6: 6 | H6: Phase 1 | I6: Sliding Window, Strings | J6: Variable window is trickier — master contraction logic | K6: ⬜ Not Started
A7: 4 | B7: Stack | C7: LIFO, monotonic stack, call stack simulation | D7: Next greater/smaller element, parenthesis matching, calculator eval | E7: Valid Parentheses (20), Min Stack (155), Evaluate Reverse Polish (150), Generate Parentheses (22), Daily Temperatures (739), Car Fleet (853), Largest Rectangle in Histogram (84) | F7: E/M/H | G7: 7 | H7: Phase 2 | I7: Stack, Monotonic Stack | J7: Monotonic stack pattern appears often in contests | K7: ⬜ Not Started
A8: 5 | B8: Linked Lists | C8: Node structure, pointer manipulation, dummy nodes, cycle detection | D8: Fast/slow pointers, reversal, merge, intersection | E8: Reverse Linked List (206), Merge Two Sorted Lists (21), Reorder List (143), Remove Nth Node (19), Copy List with Random Pointer (138), LRU Cache (146), Merge K Sorted Lists (23), Reverse Nodes in K-Group (25) | F8: E/M/H | G8: 8 | H8: Phase 2 | I8: Linked List, Two Pointers | J8: Draw diagrams; pointer bugs are common | K8: ⬜ Not Started
A9: 6 | B9: Binary Search | C9: Search space reduction, invariant maintenance, boundary conditions | D9: Left/right bisect, rotated array, search on answer (parametric) | E9: Binary Search (704), Search in Rotated Array (33), Find Minimum in Rotated Array (153), Search 2D Matrix (74), Koko Eating Bananas (875), Find in Mountain Array (1095), Median of Two Sorted Arrays (4) | F9: E/M/H | G9: 7 | H9: Phase 2 | I9: Binary Search, Divide & Conquer | J9: Off-by-one in lo/hi is the classic bug | K9: ⬜ Not Started
A10: 7 | B10: Trees — Basics | C10: DFS (pre/in/post), BFS (level order), height, diameter, LCA | D10: Recursive tree traversal, iterative with stack/queue | E10: Invert Binary Tree (226), Max Depth (104), Diameter of Binary Tree (543), Balanced Binary Tree (110), Same Tree (100), Subtree of Another Tree (572), Level Order Traversal (102), Right Side View (199) | F10: E/M | G10: 8 | H10: Phase 3 | I10: Trees, DFS, BFS | J10: Understand recursion return values clearly | K10: ⬜ Not Started
A11: 8 | B11: Trees — BST | C11: BST property, in-order gives sorted order, predecessor/successor | D11: Validation, range checks, kth smallest via in-order | E11: Lowest Common Ancestor BST (235), Insert into BST (701), Delete Node BST (450), Kth Smallest (230), Validate BST (98), Construct BST from Preorder (1008) | F11: E/M | G11: 6 | H11: Phase 3 | I11: BST, In-order | J11: In-order traversal is the BST superpower | K11: ⬜ Not Started
A12: 9 | B12: Tries | C12: Prefix tree, TrieNode structure, insert/search/startsWith | D12: Word search with backtracking, auto-complete, prefix frequency | E12: Implement Trie (208), Design Add and Search Words (211), Word Search II (212), Longest Word in Dictionary (720) | F12: M/H | G12: 4 | H12: Phase 3 | I12: Trie, Strings | J12: Word Search II combines Trie + backtracking | K12: ⬜ Not Started
A13: 10 | B13: Heap / Priority Queue | C13: Min-heap, max-heap, heapify, heap invariant, k-way merge | D13: Top-K pattern, streaming median, interval scheduling | E13: Kth Largest Element (215), K Closest Points (973), Task Scheduler (621), Design Twitter (355), Find Median from Data Stream (295), Merge K Sorted Lists (23), Top K Frequent (347) | F13: M/H | G13: 7 | H13: Phase 5 | I13: Heap, Priority Queue | J13: Python: heapq; Java: PriorityQueue; negate for max-heap | K13: ⬜ Not Started
A14: 11 | B14: Graphs — BFS/DFS | C14: Adjacency list/matrix, visited array, connected components, cycle detection | D14: Island counting, shortest path (BFS), topological sort | E14: Number of Islands (200), Clone Graph (133), Pacific Atlantic Water Flow (417), Surrounded Regions (130), Rotting Oranges (994), Walls and Gates (286), Course Schedule (207), Course Schedule II (210) | F14: M/H | G14: 8 | H14: Phase 3 | I14: Graph, BFS, DFS | J14: Know both recursive DFS and iterative BFS | K14: ⬜ Not Started
A15: 12 | B15: Advanced Graphs | C15: Dijkstra, Bellman-Ford, Union-Find, Minimum Spanning Tree, SCC | D15: Shortest paths, disjoint sets, Kruskal, Floyd-Warshall | E15: Network Delay Time (743), Swim in Rising Water (778), Alien Dictionary (269), Cheapest Flights K Stops (787), Min Cost to Connect Points (1584), Reconstruct Itinerary (332), Word Ladder (127) | F15: H | G15: 7 | H15: Phase 5 | I15: Dijkstra, Union-Find, MST | J15: Understand when to use which algorithm | K15: ⬜ Not Started
... A23: 20 | B23: Advanced Trees | C23: AVL concepts, Segment Trees, Fenwick Tree, Red-Black concepts | D23: Range queries, lazy propagation, order statistics | E23: Range Sum Query Mutable (307), Count of Smaller Numbers After Self (315), Reverse Pairs (493), My Calendar I/II (729/731), Falling Squares (699) | F23: H | G23: 5 | H23: Phase 6 | I23: Segment Tree, BIT, Advanced Trees | J23: Understand concept; BIT often sufficient in interviews | K23: ⬜ Not Started

Sheet 📊 Problem Tracker
A1: 📊 MASTER PROBLEM TRACKER — Mark ✅ Status here. All list sheets auto-sync via formula.
A3: # | B3: LC # | C3: Problem Title | D3: Topics | E3: Difficulty | F3: ✅ Status | G3: Date Solved | H3: Time (min) | I3: Key Insight / Pattern | J3: Retry? | K3: Retry Date | L3: Appears In | M3: Notes | N3: How to Solve | O3: Time Complexity | P3: Space Complexity | Q3: 🔗 LeetCode URL
A4: 1 | B4: 1 | C4: Two Sum | D4: Array, Hashing | E4: Easy | I4: HashMap (One-Pass) | L4: Amazon, Apple, Blind75, Google, Grind169, Grind75, Meta, Microsoft, NeetCode150, Uber | N4: HashMap (One-Pass): Store each number's index in a map. For each element, check if (target - num) exists before inserting. | O4: O(n) | P4: O(n) | Q4: https://leetcode.com/problems/two-sum/
A5: 2 | B5: 2 | C5: Add Two Numbers | D5: Linked List, Math | E5: Medium | I5: Linked List Traversal with Carry | L5: Amazon, Apple, Google, Grind169, Meta, Microsoft, Uber | N5: Linked List Traversal with Carry: Traverse both lists simultaneously, add digits plus carry, and handle remaining carry at the end. | O5: O(max(m, n)) | P5: O(max(m, n)) | Q5: https://leetcode.com/problems/add-two-numbers/
A6: 3 | B6: 3 | C6: Longest Substring Without Repeating Characters | D6: String, Sliding Window | E6: Medium | I6: Sliding Window + HashSet | L6: Amazon, Apple, Blind75, Google, Grind169, Grind75, Meta, Microsoft, NeetCode150, Uber | N6: Sliding Window + HashSet: Expand right pointer. If a char repeats, shrink left until removed. Track max window size. | O6: O(n) | P6: O(min(n, charset)) | Q6: https://leetcode.com/problems/longest-substring-without-repeating-characters/
A7: 4 | B7: 4 | C7: Median of Two Sorted Arrays | D7: Array, Binary Search | E7: Hard | I7: Binary Search on Smaller Array | L7: Amazon, Apple, Google, Grind169, Meta, Microsoft, NeetCode150, Uber | N7: Binary Search on Smaller Array: Partition the smaller array so all left-side values ≤ right-side values. Adjust lo/hi based on whether left-side max exceeds right-side min. | O7: O(log(min(m, n))) | P7: O(1) | Q7: https://leetcode.com/problems/median-of-two-sorted-arrays/
A8: 5 | B8: 5 | C8: Longest Palindromic Substring | D8: String, DP | E8: Medium | I8: Expand Around Center | L8: Amazon, Apple, Blind75, Google, Grind169, Grind75, Meta, Microsoft, NeetCode150, Uber | N8: Expand Around Center: For every character and gap center, expand outward while characters match and track the longest palindrome. | O8: O(n²) | P8: O(1) | Q8: https://leetcode.com/problems/longest-palindromic-substring/
A9: 6 | B9: 6 | C9: Zigzag Conversion | D9: String, Math | E9: Medium | I9: Row Assignment | L9: Amazon, Apple, Google, Meta | N9: Row Assignment: Simulate zigzag movement with a direction flag and append each character to the correct row. | O9: O(n) | P9: O(n) | Q9: https://leetcode.com/problems/zigzag-conversion/
A10: 7 | B10: 7 | C10: Reverse Integer | D10: Math | E10: Medium | I10: Math with Overflow Check | L10: Amazon, Apple, Google, Grind169, Meta, Microsoft, NeetCode150, Uber | N10: Math with Overflow Check: Pop digits one by one and push into result after checking INT_MIN/INT_MAX overflow boundaries. | O10: O(log n) | P10: O(1) | Q10: https://leetcode.com/problems/reverse-integer/
A11: 8 | B11: 8 | C11: String to Integer (atoi) | D11: String, Math | E11: Medium | I11: State Machine String Parsing | L11: Amazon, Apple, Google, Grind169, Grind75, Meta, Microsoft, Uber | N11: State Machine String Parsing: Skip spaces, handle sign, parse digits until a non-digit, and clamp to integer bounds. | O11: O(n) | P11: O(1) | Q11: https://leetcode.com/problems/string-to-integer-atoi/
A12: 9 | B12: 9 | C12: Palindrome Number | D12: Math | E12: Easy | I12: Revert Half the Number | L12: Amazon, Google, Grind169, Meta, Microsoft | N12: Revert Half the Number: Reverse the second half of the digits and compare it with the first half. | O12: O(log n) | P12: O(1) | Q12: https://leetcode.com/problems/palindrome-number/
A13: 10 | B13: 10 | C13: Regular Expression Matching | D13: String, DP | E13: Hard | I13: 2D DP - Regex Match | L13: Amazon, Apple, Google, Meta, Microsoft, NeetCode150, Uber | N13: 2D DP - Regex Match: Let dp[i][j] mean s[:i] matches p[:j]. Handle '*' as skip previous token or consume matching char. | O13: O(m·n) | P13: O(m·n) | Q13: https://leetcode.com/problems/regular-expression-matching/
A14: 11 | B14: 11 | C14: Container With Most Water | D14: Array, Two Pointers | E14: Medium | I14: Two Pointers from Both Ends | L14: Amazon, Apple, Blind75, Google, Grind169, Grind75, Meta, Microsoft, NeetCode150, Uber | N14: Two Pointers from Both Ends: Move the shorter height inward because it is the limiting side; update max area each step. | O14: O(n) | P14: O(1) | Q14: https://leetcode.com/problems/container-with-most-water/
A15: 12 | B15: 12 | C15: Integer to Roman | D15: String, Math | E15: Medium | I15: Greedy - Largest Symbol First | L15: Amazon, Google, Meta, Microsoft | N15: Greedy - Largest Symbol First: Process Roman values from largest to smallest, append symbols while subtracting their value. | O15: O(1) | P15: O(1) | Q15: https://leetcode.com/problems/integer-to-roman/
... A54: 51 | B54: 51 | C54: N-Queens | D54: Array, Backtracking | E54: Hard | I54: Backtracking | L54: Amazon, Google, Grind169, Meta, Microsoft, NeetCode150 | N54: Backtracking: Build candidates recursively, prune invalid choices early, add a result at the base case, and undo choices before returning. | O54: O(branch^depth) | P54: O(depth) | Q54: https://leetcode.com/problems/n-queens/
A55: 52 | B55: 52 | C55: N-Queens II | D55: Array, Backtracking | E55: Hard | I55: Backtracking | N55: Backtracking: Build candidates recursively, prune invalid choices early, add a result at the base case, and undo choices before returning. | O55: O(branch^depth) | P55: O(depth) | Q55: https://leetcode.com/problems/n-queens-ii/
A56: 53 | B56: 53 | C56: Maximum Subarray | D56: Array, DP | E56: Medium | I56: Kadane's Algorithm | L56: Amazon, Apple, Blind75, Google, Grind169, Grind75, Meta, Microsoft, NeetCode150, Uber | N56: Kadane's Algorithm: Track best subarray ending at current index and global best; restart when current value is better. | O56: O(n) | P56: O(1) | Q56: https://leetcode.com/problems/maximum-subarray/
A57: 54 | B57: 54 | C57: Spiral Matrix | D57: Array, Matrix | E57: Medium | I57: Boundary Shrinking | L57: Amazon, Apple, Blind75, Google, Grind169, Grind75, Meta, Microsoft, NeetCode150, Uber | N57: Boundary Shrinking: Maintain top, bottom, left, and right boundaries and traverse right, down, left, up while shrinking. | O57: O(m·n) | P57: O(1) | Q57: https://leetcode.com/problems/spiral-matrix/
A58: 55 | B58: 55 | C58: Jump Game | D58: Array, Greedy | E58: Medium | I58: Greedy - Track Max Reachable | L58: Amazon, Apple, Blind75, Google, Grind169, Meta, Microsoft, NeetCode150 | N58: Greedy - Track Max Reachable: Track the farthest reachable index and fail if the current index is beyond it. | O58: O(n) | P58: O(1) | Q58: https://leetcode.com/problems/jump-game/
A59: 56 | B59: 56 | C59: Merge Intervals | D59: Array, Intervals | E59: Medium | I59: Sort by Start + Merge Overlapping | L59: Amazon, Apple, Blind75, Google, Grind169, Grind75, Meta, Microsoft, NeetCode150, Uber | N59: Sort by Start + Merge Overlapping: Sort intervals by start and merge into the previous interval when they overlap. | O59: O(n log n) | P59: O(n) | Q59: https://leetcode.com/problems/merge-intervals/
A60: 57 | B60: 57 | C60: Insert Interval | D60: Array, Intervals | E60: Medium | I60: Three Phases | L60: Amazon, Apple, Blind75, Google, Grind169, Grind75, Microsoft, NeetCode150, Uber | N60: Three Phases: Before, Overlap, After: Add intervals before new interval, merge all overlaps with it, then append the rest. | O60: O(n) | P60: O(n) | Q60: https://leetcode.com/problems/insert-interval/
A61: 58 | B61: 58 | C61: Length of Last Word | D61: String | E61: Easy | I61: Scan from Right | L61: Amazon, Google, Meta, Microsoft | N61: Scan from Right: Skip trailing spaces, then count characters until the previous space. | O61: O(n) | P61: O(1) | Q61: https://leetcode.com/problems/length-of-last-word/
A62: 59 | B62: 59 | C62: Spiral Matrix II | D62: Array, Matrix | E62: Medium | I62: Boundary Simulation | L62: Amazon | N62: Boundary Simulation: Maintain top/bottom/left/right bounds and fill 1..n^2 while walking right, down, left, up, shrinking a bound after each edge. | O62: O(n^2) | P62: O(1) | Q62: https://leetcode.com/problems/spiral-matrix-ii/
A63: 60 | B63: 60 | C63: Permutation Sequence | D63: Math, Backtracking | E63: Hard | I63: Factorial Number System | L63: Amazon, Google | N63: Factorial Number System: Use factorial blocks to choose each digit of the kth permutation from remaining numbers. | O63: O(n²) | P63: O(n) | Q63: https://leetcode.com/problems/permutation-sequence/
A64: 61 | B64: 61 | C64: Rotate List | D64: Linked List | E64: Medium | I64: Find New Tail at Position (n-k%len) | L64: Amazon, Google, Grind169 | N64: Find New Tail at Position (n-k%len): Compute length, connect tail to head, then break at the new tail position. | O64: O(n) | P64: O(1) | Q64: https://leetcode.com/problems/rotate-list/
A65: 62 | B65: 62 | C65: Unique Paths | D65: DP, Math | E65: Medium | I65: DP - Unique Paths Grid | L65: Amazon, Blind75, Google, Grind169, Grind75, Meta, Microsoft, NeetCode150 | N65: DP - Unique Paths Grid: Use dp[i][j] = top + left, with first row and column initialized to 1. | O65: O(m·n) | P65: O(n) | Q65: https://leetcode.com/problems/unique-paths/
A66: 63 | B66: 63 | C66: Unique Paths II | D66: Array, Matrix, DP | E66: Medium | I66: Grid DP | L66: Amazon | N66: Grid DP: dp[j] = paths to a cell = 0 if obstacle else dp[j] (from above) + dp[j-1] (from left); use a 1D rolling row. | O66: O(m*n) | P66: O(n) | Q66: https://leetcode.com/problems/unique-paths-ii/
A67: 64 | B67: 64 | C67: Minimum Path Sum | D67: Array, Matrix, DP | E67: Medium | I67: DP - Min Path Sum | L67: Amazon, Google, Microsoft, Uber | N67: DP - Min Path Sum: Accumulate min cost from top or left; use the grid in-place when allowed. | O67: O(m·n) | P67: O(n) | Q67: https://leetcode.com/problems/minimum-path-sum/
... A79: 76 | B79: 76 | C79: Minimum Window Substring | D79: String, Sliding Window, Hashing | E79: Hard | I79: Sliding Window with Need/Have Counters | L79: Amazon, Apple, Blind75, Google, Grind169, Grind75, Meta, NeetCode150, Uber | N79: Sliding Window with Need/Have Counters: Expand right to satisfy required counts, shrink left while valid, and track the smallest window. | O79: O(n + m) | P79: O(k) | Q79: https://leetcode.com/problems/minimum-window-substring/
A80: 77 | B80: 77 | C80: Combinations | D80: Backtracking | E80: Medium | I80: Backtracking - Combinations | N80: Backtracking - Combinations: Iterate from start to n, add current to path, recurse for k-1, then backtrack. | O80: O(n) | P80: O(n) | Q80: https://leetcode.com/problems/combinations/
A81: 78 | B81: 78 | C81: Subsets | D81: Array, Backtracking | E81: Medium | I81: Backtracking / Iterative Subsets | L81: Amazon, Google, Grind169, Grind75, Meta, Microsoft, NeetCode150, Uber | N81: Backtracking / Iterative Subsets: For each number, either include or exclude it; collect all generated subsets. | O81: O(n · 2^n) | P81: O(n) | Q81: https://leetcode.com/problems/subsets/
A82: 79 | B82: 79 | C82: Word Search | D82: Array, Matrix, DFS | E82: Medium | I82: DFS Backtracking on Grid | L82: Amazon, Apple, Blind75, Google, Grind169, Grind75, Meta, Microsoft, NeetCode150, Uber | N82: DFS Backtracking on Grid: DFS from each matching start cell, mark visited in-place, explore 4 directions, then restore. | O82: O(m·n·4^L) | P82: O(L) | Q82: https://leetcode.com/problems/word-search/
A83: 80 | B83: 80 | C83: Remove Duplicates from Sorted Array II | D83: Array, Two Pointers | E83: Medium | I83: Two Pointers - Allow At Most 2 | L83: Amazon, Google | N83: Two Pointers - Allow At Most 2: Use a write pointer and keep an element only if it differs from the value two kept positions back. | O83: O(n) | P83: O(1) | Q83: https://leetcode.com/problems/remove-duplicates-from-sorted-array-ii/
A84: 81 | B84: 81 | C84: Search in Rotated Sorted Array II | D84: Array, Binary Search | E84: Medium | I84: Binary Search with Duplicate Handling | L84: Amazon, Uber | N84: Binary Search with Duplicate Handling: Use rotated binary search; when endpoints equal mid, shrink both ends. | O84: O(log n) avg, O(n) worst | P84: O(1) | Q84: https://leetcode.com/problems/search-in-rotated-sorted-array-ii/
A85: 82 | B85: 82 | C85: Remove Duplicates from Sorted List II | D85: Linked List | E85: Medium | I85: Linked List Pointers | L85: Apple | N85: Linked List Pointers: Use dummy nodes and careful prev/curr/next pointer updates to handle edge cases cleanly. | O85: O(n) | P85: O(1) | Q85: https://leetcode.com/problems/remove-duplicates-from-sorted-list-ii/
A86: 83 | B86: 83 | C86: Remove Duplicates from Sorted List | D86: Linked List | E86: Easy | I86: Linked List Pointers | L86: Amazon, Google | N86: Linked List Pointers: Use dummy nodes and careful prev/curr/next pointer updates to handle edge cases cleanly. | O86: O(n) | P86: O(1) | Q86: https://leetcode.com/problems/remove-duplicates-from-sorted-list/
A87: 84 | B87: 84 | C87: Largest Rectangle in Histogram | D87: Array, Stack, Monotonic Stack | E87: Hard | I87: Monotonic Stack - Extend Rectangles | L87: Amazon, Apple, Google, Grind169, Grind75, Meta, Microsoft, NeetCode150, Uber | N87: Monotonic Stack - Extend Rectangles: Maintain increasing bar indices; when a shorter bar appears, pop and compute rectangle area. | O87: O(n) | P87: O(n) | Q87: https://leetcode.com/problems/largest-rectangle-in-histogram/
A88: 85 | B88: 85 | C88: Maximal Rectangle | D88: Array, Matrix, Stack, DP | E88: Hard | I88: Extend LC84 Row by Row | L88: Amazon, Google, Meta, Microsoft | N88: Extend LC84 Row by Row: Convert each matrix row to histogram heights and apply largest rectangle in histogram. | O88: O(m·n) | P88: O(n) | Q88: https://leetcode.com/problems/maximal-rectangle/
A89: 86 | B89: 86 | C89: Partition List | D89: Linked List | E89: Medium | I89: Two Dummy Lists | L89: Amazon | N89: Two Dummy Lists: Build a 'less than x' list and a '>= x' list in one pass, then splice them together. | O89: O(n) | P89: O(1) | Q89: https://leetcode.com/problems/partition-list/
A90: 87 | B90: 88 | C90: Merge Sorted Array | D90: Array, Two Pointers | E90: Easy | I90: Three Pointers Merge from Back | L90: Amazon, Apple, Google, Meta, Microsoft | N90: Three Pointers Merge from Back: Merge nums2 into nums1 from the end so existing nums1 values are not overwritten. | O90: O(m+n) | P90: O(1) | Q90: https://leetcode.com/problems/merge-sorted-array/
...

Sheet 📈 Progress Dashboard
A1: 📈 AGGREGATE PROGRESS DASHBOARD
A2: Mark each problem's Status in the 📊 Problem Tracker (column F). Everything below updates automatically — the Tracker is the single source of truth.
A4: OVERALL
A5: Total Unique | B5: ✅ Solved | C5: 🚧 In Progress | D5: 🔁 Retry | E5: Remaining | F5: % Complete
A6: =COUNT('📊 Problem Tracker'!$B$4:$B$1200) -> 880 | B6: =COUNTIF('📊 Problem Tracker'!$F$4:$F$1200,"✅ Solved") -> 0 | C6: =COUNTIF('📊 Problem Tracker'!$F$4:$F$1200,"🚧 In Progress") -> 0 | D6: =COUNTIF('📊 Problem Tracker'!$F$4:$F$1200,"🔁 Retry") -> 0 | E6: =A6-B6 -> 880 | F6: =IFERROR(B6/A6,0) -> 0
A8: BY DIFFICULTY
A9: Difficulty | B9: Total | C9: ✅ Solved | D9: % Complete | E9: Progress
A10: Easy | B10: =COUNTIF('📊 Problem Tracker'!$E$4:$E$1200,"Easy") -> 233 | C10: =COUNTIFS('📊 Problem Tracker'!$E$4:$E$1200,"Easy",'📊 Problem Tracker'!$F$4:$F$1200,"✅ Solved") -> 0 | D10: =IFERROR(C10/B10,0) -> 0 | E10: =REPT("█",ROUND(D10*10,0))&REPT("░",10-ROUND(D10*10,0)) -> ░░░░░░░░░░
A11: Medium | B11: =COUNTIF('📊 Problem Tracker'!$E$4:$E$1200,"Medium") -> 503 | C11: =COUNTIFS('📊 Problem Tracker'!$E$4:$E$1200,"Medium",'📊 Problem Tracker'!$F$4:$F$1200,"✅ Solved") -> 0 | D11: =IFERROR(C11/B11,0) -> 0 | E11: =REPT("█",ROUND(D11*10,0))&REPT("░",10-ROUND(D11*10,0)) -> ░░░░░░░░░░
A12: Hard | B12: =COUNTIF('📊 Problem Tracker'!$E$4:$E$1200,"Hard") -> 144 | C12: =COUNTIFS('📊 Problem Tracker'!$E$4:$E$1200,"Hard",'📊 Problem Tracker'!$F$4:$F$1200,"✅ Solved") -> 0 | D12: =IFERROR(C12/B12,0) -> 0 | E12: =REPT("█",ROUND(D12*10,0))&REPT("░",10-ROUND(D12*10,0)) -> ░░░░░░░░░░
A13: BY PROBLEM LIST
A14: List | B14: Total | C14: ✅ Solved | D14: 🔁 Retry | E14: Remaining | F14: % Complete | G14: Progress
A15: 🎯 Blind 75 | B15: =COUNTIF('📊 Problem Tracker'!$L$4:$L$1200,"*Blind75*") -> 75 | C15: =COUNTIFS('📊 Problem Tracker'!$L$4:$L$1200,"*Blind75*",'📊 Problem Tracker'!$F$4:$F$1200,"✅ Solved") -> 0 | D15: =COUNTIFS('📊 Problem Tracker'!$L$4:$L$1200,"*Blind75*",'📊 Problem Tracker'!$F$4:$F$1200,"🔁 Retry") -> 0 | E15: =B15-C15 -> 75 | F15: =IFERROR(C15/B15,0) -> 0 | G15: =REPT("█",ROUND(F15*10,0))&REPT("░",10-ROUND(F15*10,0)) -> ░░░░░░░░░░
A16: ⚡ Grind 75 | B16: =COUNTIF('📊 Problem Tracker'!$L$4:$L$1200,"*Grind75*") -> 75 | C16: =COUNTIFS('📊 Problem Tracker'!$L$4:$L$1200,"*Grind75*",'📊 Problem Tracker'!$F$4:$F$1200,"✅ Solved") -> 0 | D16: =COUNTIFS('📊 Problem Tracker'!$L$4:$L$1200,"*Grind75*",'📊 Problem Tracker'!$F$4:$F$1200,"🔁 Retry") -> 0 | E16: =B16-C16 -> 75 | F16: =IFERROR(C16/B16,0) -> 0 | G16: =REPT("█",ROUND(F16*10,0))&REPT("░",10-ROUND(F16*10,0)) -> ░░░░░░░░░░
A17: 🔥 Grind 169 | B17: =COUNTIF('📊 Problem Tracker'!$L$4:$L$1200,"*Grind169*") -> 169 | C17: =COUNTIFS('📊 Problem Tracker'!$L$4:$L$1200,"*Grind169*",'📊 Problem Tracker'!$F$4:$F$1200,"✅ Solved") -> 0 | D17: =COUNTIFS('📊 Problem Tracker'!$L$4:$L$1200,"*Grind169*",'📊 Problem Tracker'!$F$4:$F$1200,"🔁 Retry") -> 0 | E17: =B17-C17 -> 169 | F17: =IFERROR(C17/B17,0) -> 0 | G17: =REPT("█",ROUND(F17*10,0))&REPT("░",10-ROUND(F17*10,0)) -> ░░░░░░░░░░
A18: 🚀 NeetCode 150 | B18: =COUNTIF('📊 Problem Tracker'!$L$4:$L$1200,"*NeetCode150*") -> 141 | C18: =COUNTIFS('📊 Problem Tracker'!$L$4:$L$1200,"*NeetCode150*",'📊 Problem Tracker'!$F$4:$F$1200,"✅ Solved") -> 0 | D18: =COUNTIFS('📊 Problem Tracker'!$L$4:$L$1200,"*NeetCode150*",'📊 Problem Tracker'!$F$4:$F$1200,"🔁 Retry") -> 0 | E18: =B18-C18 -> 141 | F18: =IFERROR(C18/B18,0) -> 0 | G18: =REPT("█",ROUND(F18*10,0))&REPT("░",10-ROUND(F18*10,0)) -> ░░░░░░░░░░
A19: 🔵 Google | B19: =COUNTIF('📊 Problem Tracker'!$L$4:$L$1200,"*Google*") -> 310 | C19: =COUNTIFS('📊 Problem Tracker'!$L$4:$L$1200,"*Google*",'📊 Problem Tracker'!$F$4:$F$1200,"✅ Solved") -> 0 | D19: =COUNTIFS('📊 Problem Tracker'!$L$4:$L$1200,"*Google*",'📊 Problem Tracker'!$F$4:$F$1200,"🔁 Retry") -> 0 | E19: =B19-C19 -> 310 | F19: =IFERROR(C19/B19,0) -> 0 | G19: =REPT("█",ROUND(F19*10,0))&REPT("░",10-ROUND(F19*10,0)) -> ░░░░░░░░░░
A20: 🍎 Apple | B20: =COUNTIF('📊 Problem Tracker'!$L$4:$L$1200,"*Apple*") -> 298 | C20: =COUNTIFS('📊 Problem Tracker'!$L$4:$L$1200,"*Apple*",'📊 Problem Tracker'!$F$4:$F$1200,"✅ Solved") -> 0 | D20: =COUNTIFS('📊 Problem Tracker'!$L$4:$L$1200,"*Apple*",'📊 Problem Tracker'!$F$4:$F$1200,"🔁 Retry") -> 0 | E20: =B20-C20 -> 298 | F20: =IFERROR(C20/B20,0) -> 0 | G20: =REPT("█",ROUND(F20*10,0))&REPT("░",10-ROUND(F20*10,0)) -> ░░░░░░░░░░
A21: 🔷 Meta | B21: =COUNTIF('📊 Problem Tracker'!$L$4:$L$1200,"*Meta*") -> 225 | C21: =COUNTIFS('📊 Problem Tracker'!$L$4:$L$1200,"*Meta*",'📊 Problem Tracker'!$F$4:$F$1200,"✅ Solved") -> 0 | D21: =COUNTIFS('📊 Problem Tracker'!$L$4:$L$1200,"*Meta*",'📊 Problem Tracker'!$F$4:$F$1200,"🔁 Retry") -> 0 | E21: =B21-C21 -> 225 | F21: =IFERROR(C21/B21,0) -> 0 | G21: =REPT("█",ROUND(F21*10,0))&REPT("░",10-ROUND(F21*10,0)) -> ░░░░░░░░░░
A22: 🪟 Microsoft | B22: =COUNTIF('📊 Problem Tracker'!$L$4:$L$1200,"*Microsoft*") -> 218 | C22: =COUNTIFS('📊 Problem Tracker'!$L$4:$L$1200,"*Microsoft*",'📊 Problem Tracker'!$F$4:$F$1200,"✅ Solved") -> 0 | D22: =COUNTIFS('📊 Problem Tracker'!$L$4:$L$1200,"*Microsoft*",'📊 Problem Tracker'!$F$4:$F$1200,"🔁 Retry") -> 0 | E22: =B22-C22 -> 218 | F22: =IFERROR(C22/B22,0) -> 0 | G22: =REPT("█",ROUND(F22*10,0))&REPT("░",10-ROUND(F22*10,0)) -> ░░░░░░░░░░
A23: 🚗 Uber | B23: =COUNTIF('📊 Problem Tracker'!$L$4:$L$1200,"*Uber*") -> 183 | C23: =COUNTIFS('📊 Problem Tracker'!$L$4:$L$1200,"*Uber*",'📊 Problem Tracker'!$F$4:$F$1200,"✅ Solved") -> 0 | D23: =COUNTIFS('📊 Problem Tracker'!$L$4:$L$1200,"*Uber*",'📊 Problem Tracker'!$F$4:$F$1200,"🔁 Retry") -> 0 | E23: =B23-C23 -> 183 | F23: =IFERROR(C23/B23,0) -> 0 | G23: =REPT("█",ROUND(F23*10,0))&REPT("░",10-ROUND(F23*10,0)) -> ░░░░░░░░░░
A24: 📦 Amazon | B24: =COUNTIF('📊 Problem Tracker'!$L$4:$L$1200,"*Amazon*") -> 659 | C24: =COUNTIFS('📊 Problem Tracker'!$L$4:$L$1200,"*Amazon*",'📊 Problem Tracker'!$F$4:$F$1200,"✅ Solved") -> 0 | D24: =COUNTIFS('📊 Problem Tracker'!$L$4:$L$1200,"*Amazon*",'📊 Problem Tracker'!$F$4:$F$1200,"🔁 Retry") -> 0 | E24: =B24-C24 -> 659 | F24: =IFERROR(C24/B24,0) -> 0 | G24: =REPT("█",ROUND(F24*10,0))&REPT("░",10-ROUND(F24*10,0)) -> ░░░░░░░░░░
A26: DSA TOPIC MASTERY
A27: Mastery Level | B27: # Topics
A28: ⬜ Not Started | B28: =COUNTIF('🧠 DSA Topics & Problems'!$K$4:$K$23,"⬜ Not Started") -> 20
A29: 📖 Learning | B29: =COUNTIF('🧠 DSA Topics & Problems'!$K$4:$K$23,"📖 Learning") -> 0
A30: 🛠️ Practiced | B30: =COUNTIF('🧠 DSA Topics & Problems'!$K$4:$K$23,"🛠️ Practiced") -> 0
A31: 💪 Confident | B31: =COUNTIF('🧠 DSA Topics & Problems'!$K$4:$K$23,"💪 Confident") -> 0
A32: 🏆 Mastered | B32: =COUNTIF('🧠 DSA Topics & Problems'!$K$4:$K$23,"🏆 Mastered") -> 0
A34: SYSTEM DESIGN
A35: Track | B35: Total | C35: ✅ Done | D35: % Complete | E35: Progress
A36: Mock Designs | B36: =COUNTA('🏗️ System Design'!B29:B44) -> 16 | C36: =COUNTIF('🏗️ System Design'!J29:J44,"✅ Done") -> 0 | D36: =IFERROR(C36/B36,0) -> 0 | E36: =REPT("█",ROUND(D36*10,0))&REPT("░",10-ROUND(D36*10,0)) -> ░░░░░░░░░░
A37: Building Blocks | B37: =COUNTA('🏗️ System Design'!B7:B24) -> 18 | C37: =COUNTIF('🏗️ System Design'!J7:J24,"✅ Covered") -> 0 | D37: =IFERROR(C37/B37,0) -> 0 | E37: =REPT("█",ROUND(D37*10,0))&REPT("░",10-ROUND(D37*10,0)) -> ░░░░░░░░░░

Sheet 🏗️ System Design
A1: 🏗️ SYSTEM DESIGN — CONCEPTS, FRAMEWORKS & MOCK DESIGNS
A3: SD INTERVIEW FRAMEWORK: Clarify Requirements → Estimate Scale → High-Level Design → Deep Dive → Trade-offs → Bottlenecks
A5: CORE BUILDING BLOCKS — Must Know Before Any Design
A6: # | B6: Building Block | C6: What It Does | D6: When to Use | E6: Key Trade-offs | F6: Interview Keywords | G6: Phase | H6: Study Resource | I6: Depth Required | J6: ✓ Covered
A7: 1 | B7: DNS & CDN | C7: Domain resolution; edge caching of static/dynamic content | D7: Any global-scale service | E7: Cache invalidation; TTL vs consistency | F7: Anycast, PoP, Cache-Control, CloudFront | G7: Phase 1 | H7: ByteByteGo Cap 1 | I7: Medium | J7: ⬜ Not Started
A8: 2 | B8: Load Balancer | C8: Distributes traffic across servers; health checks | D8: Any service with >1 server | E8: L4 vs L7; sticky sessions; SSL termination | F8: Round-robin, Least-conn, Consistent hash, NGINX | G8: Phase 1 | H8: ByteByteGo Cap 2 | I8: High | J8: ⬜ Not Started
A9: 3 | B9: Horizontal Scaling | C9: Add more instances instead of bigger instances | D9: Stateless services | E9: Stateless design; session externalization | F9: Stateless, session store, auto-scaling group | G9: Phase 1 | H9: Designing Data-Intensive Apps | I9: High | J9: ⬜ Not Started
A10: 4 | B10: Caching | C10: Redis/Memcached for hot data; multiple layers | D10: Read-heavy workloads | E10: Consistency, invalidation, thundering herd | F10: Cache-aside, Write-through, TTL, Eviction, LRU | G10: Phase 1 | H10: ByteByteGo Cap 4 | I10: High | J10: ⬜ Not Started
A11: 5 | B11: Message Queues | C11: Async decoupling; Kafka, RabbitMQ, SQS | D11: Event-driven, background jobs, fan-out | E11: At-least-once vs exactly-once; ordering | F11: Producer-Consumer, Pub-Sub, Partition, Offset, DLQ | G11: Phase 2 | H11: Kafka Definitive Guide | I11: High | J11: ⬜ Not Started
A12: 6 | B12: Databases — SQL | C12: ACID transactions, relational model, B-tree index | D12: Structured relational data, complex queries | E12: Vertical scale limits; shard complexity | F12: Normalization, Index, ACID, Join, Partition | G12: Phase 2 | H12: Use The Index Luke | I12: High | J12: ⬜ Not Started
A13: 7 | B13: Databases — NoSQL | C13: Document, KV, Wide-column, Graph stores | D13: Flexible schema, massive scale | E13: Eventual consistency; limited query patterns | F13: DynamoDB, Cassandra, MongoDB, BASE, CAP | G13: Phase 2 | H13: DDIA Ch 2 | I13: High | J13: ⬜ Not Started
A14: 8 | B14: Database Sharding | C14: Horizontal partitioning across DB nodes | D14: When single DB can't handle load | E14: Hotspot keys, cross-shard joins, rebalancing | F14: Shard key, Consistent hashing, Hotspot | G14: Phase 3 | H14: DDIA Ch 6 | I14: High | J14: ⬜ Not Started
A15: 9 | B15: Replication | C15: Primary-replica; multi-master for HA | D15: Read scaling; disaster recovery | E15: Replication lag; split-brain | F15: Leader election, WAL, Replica lag, Failover | G15: Phase 3 | H15: DDIA Ch 5 | I15: High | J15: ⬜ Not Started
A16: 10 | B16: Consistent Hashing | C16: Maps keys to nodes on a hash ring | D16: Distributed caches, load balancers | E16: Virtual nodes for uniform distribution | F16: Hash ring, Virtual nodes, Rendezvous hashing | G16: Phase 3 | H16: ByteByteGo Ch 5 | I16: Medium | J16: ⬜ Not Started
A17: 11 | B17: Rate Limiting | C17: Throttle requests per user/IP/token | D17: API protection, abuse prevention | E17: Distributed counters, accuracy vs overhead | F17: Token bucket, Leaky bucket, Sliding window, Redis | G17: Phase 3 | H17: ByteByteGo Ch 4 | I17: High | J17: ⬜ Not Started
A18: 12 | B18: API Design | C18: REST vs GraphQL vs gRPC; pagination; versioning | D18: Every service boundary | E18: Coupling, backward compat, latency | F18: REST, GraphQL, gRPC, Pagination cursor, Idempotency | G18: Phase 2 | H18: API Design Patterns (Geewax) | I18: High | J18: ⬜ Not Started
... A24: 18 | B24: Security Basics | C24: AuthN/AuthZ, OAuth2, JWT, HTTPS, RBAC | D24: Every system | E24: Token revocation; over-privilege | F24: OAuth2, JWT, mTLS, RBAC, CORS, CSRF | G24: Phase 2 | H24: Auth0 Docs, OWASP | I24: Medium | J24: ⬜ Not Started
A27: SYSTEM DESIGN MOCK PROBLEMS — 1 Per Day, Timed 45–60 Minutes
A28: # | B28: System to Design | C28: Core Challenges | D28: Key Components | E28: Scale Target | F28: Bottlenecks to Discuss | G28: Trade-offs | H28: Phase | I28: Difficulty | J28: ✓ Done
A29: 1 | B29: URL Shortener (TinyURL) | C29: Hash collision, redirect latency, analytics | D29: KV store, Base62 encoding, Bloom filter | E29: 100M URLs, 10B redirects/day | F29: Cache hot URLs, DB read replicas | G29: Custom alias vs random; hash vs counter | H29: Phase 1 | I29: Beginner | J29: ⬜ Not Started
A30: 2 | B30: Rate Limiter | C30: Distributed counters, multi-data-center | D30: Redis + Lua script, sliding window | E30: 10K RPS per user | F30: Redis cluster; clock skew | G30: Exact vs approx counting; local vs global | H30: Phase 1 | I30: Beginner | J30: ⬜ Not Started
A31: 3 | B31: Key-Value Store | C31: Consistent hashing, replication, compaction | D31: Ring, LSM tree, WAL, Gossip protocol | E31: 10K writes/sec, 100K reads/sec | F31: Hot partitions, GC pauses | G31: Consistency levels; read-repair vs quorum | H31: Phase 2 | I31: Intermediate | J31: ⬜ Not Started
A32: 4 | B32: Unique ID Generator | C32: Clock skew, monotonic ordering, multi-DC | D32: Snowflake ID, UUID v4, DB sequences | E32: 100K IDs/sec, globally unique | F32: Time sync; NTP drift | G32: Ordered vs random; size tradeoffs | H32: Phase 2 | I32: Beginner | J32: ⬜ Not Started
A33: 5 | B33: Web Crawler | C33: Politeness, dedup, URL frontier priority | D33: BFS queue, Bloom filter, DNS cache, Robot.txt parser | E33: 1B pages/month | F33: DNS lookup bottleneck; duplicate content | G33: BFS vs DFS; centralized vs distributed | H33: Phase 2 | I33: Intermediate | J33: ⬜ Not Started
A34: 6 | B34: Notification System | C34: Fan-out on write vs read, delivery guarantee | D34: Kafka, push/email/SMS workers, user prefs DB | E34: 10M notifications/day | F34: Celebrity problem, mobile push limits | G34: Exactly-once vs at-least-once; freshness | H34: Phase 3 | I34: Intermediate | J34: ⬜ Not Started
A35: 7 | B35: News Feed (Facebook/Twitter) | C35: Fan-out, feed ranking, hot celebrity | D35: Write/read fan-out hybrid, Redis feed cache, ML rank | E35: 500M DAU, 5M posts/day | F35: Celeb accounts (50M followers) | G35: Hybrid fan-out threshold; pre-compute vs lazy | H35: Phase 3 | I35: Intermediate | J35: ⬜ Not Started
A36: 8 | B36: Chat System (WhatsApp) | C36: Real-time delivery, presence, message ordering | D36: WebSocket, Kafka, Cassandra (time-series), Redis presence | E36: 2B users, 100B messages/day | F36: Connection servers scaling; message ordering | G36: End-to-end encrypt; store vs ephemeral | H36: Phase 3 | I36: Intermediate | J36: ⬜ Not Started
A37: 9 | B37: Search Autocomplete | C37: Prefix trie, top-K tracking, latency budget | D37: Distributed trie, Redis ZSET, data aggregation pipeline | E37: 10M queries/sec, p99 < 100ms | F37: Trie rebalancing; stale suggestions | G37: Exact vs fuzzy; personalization | H37: Phase 4 | I37: Advanced | J37: ⬜ Not Started
A38: 10 | B38: YouTube / Video Platform | C38: Upload pipeline, streaming, CDN, transcoding | D38: Object storage, transcoding queue, CDN, HLS/DASH | E38: 1B hours viewed/day, 500h video uploaded/min | F38: Transcoding farm capacity; CDN egress cost | G38: ABR streaming; copyright detection | H38: Phase 4 | I38: Advanced | J38: ⬜ Not Started
A39: 11 | B39: Ride-Sharing (Uber) | C39: Real-time matching, location updates, surge | D39: WebSocket, geospatial index (QuadTree/S2), Kafka | E39: 5M trips/day, 500K active drivers | F39: Location update write volume; matching latency | G39: Strong vs eventual for driver location | H39: Phase 4 | I39: Advanced | J39: ⬜ Not Started
A40: 12 | B40: Hotel Booking (Airbnb) | C40: Double booking prevention, search, payments | D40: Distributed lock / idempotency, Elasticsearch, Stripe | E40: 10M listings, 1M bookings/day | F40: Race condition on last room; search freshness | G40: Optimistic vs pessimistic locking | H40: Phase 4 | I40: Advanced | J40: ⬜ Not Started
... A44: 16 | B44: Ad Click Aggregator | C44: Real-time stream + batch lambda, dedup | D44: Kafka, Flink, ClickHouse, Bloom filter dedup | E44: 1B clicks/day, report in 1 min | F44: Late data, dedup at scale | G44: Lambda vs Kappa; accuracy vs freshness | H44: Phase 6 | I44: Expert | J44: ⬜ Not Started

Sheet 🗣️ Behavioral (STAR)
A1: 🗣️ BEHAVIORAL PREP — STAR STORIES
A2: STAR = Situation · Task · Action · Result. Draft 1–2 crisp, quantified stories per competency and reuse them across questions. Keep the Result measurable (%, $, time, scale). Most rows map to an Amazon Leadership Principle — but they work for any company.
A4: STAR STORY BANK
A5: # | B5: Theme / Story Title | C5: Competency | D5: Common Questions It Answers | E5: S — Situation | F5: T — Task | G5: A — Action | H5: R — Result (quantify!) | I5: Maps To (Amazon LP) | J5: Status
A6: Ex | B6: ‹EXAMPLE — replace with your own› | C6: Ownership | D6: Took ownership beyond role | E6: A data-ingest service was dropping batches silently in production and no one owned it. | F6: I volunteered to stabilize it before the next release. | G6: Added structured logging, root-caused the dropped batches, and drove a cross-team fix. | H6: Cut data-loss incidents to ~0 and reduced on-call pages by ~70% over two months. | I6: Ownership | J6: ✅ Ready
A7: 1 | B7: Ownership | C7: Ownership | D7: Tell me about a time you took ownership of something beyond your role. | I7: Ownership | J7: ⬜ Not Drafted
A8: 2 | B8: Customer Focus | C8: Customer Focus | D8: Describe a time you went above and beyond for a customer or end user. | I8: Customer Obsession | J8: ⬜ Not Drafted
A9: 3 | B9: Failure / Lessons | C9: Failure / Lessons | D9: Tell me about a time you failed. What did you learn? | I9: Learn and Be Curious | J9: ⬜ Not Drafted
A10: 4 | B10: Conflict / Trust | C10: Conflict / Trust | D10: Describe a conflict with a teammate and how you resolved it. | I10: Earn Trust | J10: ⬜ Not Drafted
A11: 5 | B11: Disagreeing Up | C11: Disagreeing Up | D11: Tell me about a time you disagreed with your manager or a decision. | I11: Have Backbone; Disagree and Commit | J11: ⬜ Not Drafted
A12: 6 | B12: Ambiguity | C12: Ambiguity | D12: Describe a time you had to act with incomplete information. | I12: Bias for Action | J12: ⬜ Not Drafted
A13: 7 | B13: Tight Deadline | C13: Tight Deadline | D13: Tell me about a time you delivered under significant time pressure. | I13: Deliver Results | J13: ⬜ Not Drafted
A14: 8 | B14: Innovation / Simplify | C14: Innovation / Simplify | D14: Tell me about a time you invented or simplified a process. | I14: Invent and Simplify | J14: ⬜ Not Drafted
A15: 9 | B15: Highest Standards | C15: Highest Standards | D15: Tell me about a time you refused to compromise on quality. | I15: Insist on the Highest Standards | J15: ⬜ Not Drafted
A16: 10 | B16: Developing Others | C16: Developing Others | D16: Tell me about a time you mentored or grew someone. | I16: Hire and Develop the Best | J16: ⬜ Not Drafted
A17: 11 | B17: Data / Deep Dive | C17: Data / Deep Dive | D17: Tell me about a time data changed your decision. | I17: Dive Deep | J17: ⬜ Not Drafted
A18: 12 | B18: Long-Term Thinking | C18: Long-Term Thinking | D18: Tell me about a time you chose the long-term win over a quick fix. | I18: Think Big | J18: ⬜ Not Drafted
... A21: 15 | B21: Doing More with Less | C21: Doing More with Less | D21: Tell me about a time you achieved more with limited resources. | I21: Frugality | J21: ⬜ Not Drafted
A23: AMAZON LEADERSHIP PRINCIPLES — QUICK REFERENCE
A24: # | B24: Leadership Principle | C24: What It Means (one line)
A25: 1 | B25: Customer Obsession | C25: Start from the customer and work backwards; earn and keep their trust.
A26: 2 | B26: Ownership | C26: Think long-term, act on behalf of the whole company, never say 'not my job'.
A27: 3 | B27: Invent and Simplify | C27: Seek new ideas from everywhere; simplify as you scale.
A28: 4 | B28: Are Right, A Lot | C28: Strong judgment; seek diverse perspectives and disconfirm your own beliefs.
A29: 5 | B29: Learn and Be Curious | C29: Always improving; curious about new possibilities.
A30: 6 | B30: Hire and Develop the Best | C30: Raise the bar; coach others and build leaders.
A31: 7 | B31: Insist on the Highest Standards | C31: Relentlessly high bar; defects don't move downstream.
A32: 8 | B32: Think Big | C32: Bold direction that inspires results; think differently.
A33: 9 | B33: Bias for Action | C33: Speed matters; many decisions are reversible (two-way doors).
A34: 10 | B34: Frugality | C34: Do more with less; constraints breed resourcefulness.
A35: 11 | B35: Earn Trust | C35: Listen, speak candidly, treat others respectfully, admit mistakes.
A36: 12 | B36: Dive Deep | C36: Stay connected to details, audit frequently, no task beneath you.
... A40: 16 | B40: Success and Scale Bring Broad Responsibility | C40: Be humble; consider the broader impact of decisions.

Sheet 📅 16-Week Schedule
A1: 📅 16-WEEK DETAILED SCHEDULE — DSA + SYSTEM DESIGN
A3: Week | B3: Phase | C3: DSA Topic (Days 1-5) | D3: Problems to Solve | E3: Target Problem Count | F3: System Design Topic | G3: SD Deep Dive | H3: Key Goal | I3: Checkpoint
A4: 1 | B4: Phase 1 | C4: Arrays & Hashing | D4: Two Sum, Valid Anagram, Contains Duplicate, Group Anagrams, Top K Frequent, Product Except Self, Longest Consecutive Sequence | E4: 25 | F4: Scalability 101: vertical vs horizontal, CAP theorem basics | G4: Understand SLA, SLO, SLI; latency vs throughput | H4: Nail HashMap O(1) lookups | I4: Can you solve Two Sum 5 ways?
A5: 2 | B5: Phase 1 | C5: Two Pointers + Sliding Window | D5: Valid Palindrome, 3Sum, Container With Most Water, Best Time Buy/Sell, Longest Substring No Repeat, Min Window Substring | E5: 20 | F5: Load Balancers deep dive: L4 vs L7, algorithms | G5: Design a simple API gateway | H5: Master variable-window pattern | I5: Solve Min Window Substring from scratch
A6: 3 | B6: Phase 2 | C6: Stack + Queues | D6: Valid Parentheses, Min Stack, Daily Temperatures, Car Fleet, Largest Rectangle Histogram, Sliding Window Max | E6: 20 | F6: Caching: Redis internals, eviction, cache patterns | G6: Design a distributed cache (Redis-like) | H6: Monotonic stack mastery | I6: Implement LRU Cache from memory
A7: 4 | B7: Phase 2 | C7: Linked Lists | D7: Reverse LL, Merge Two Sorted, Reorder List, Remove Nth Node, LRU Cache, Merge K Sorted Lists | E7: 20 | F7: Databases: SQL indexing, query planning, ACID | G7: Design URL shortener | H7: Pointer manipulation fluency | I7: No bugs in LL reversal
A8: 5 | B8: Phase 3 | C8: Binary Search | D8: Binary Search, Search Rotated Array, Find Min Rotated, Search 2D Matrix, Koko Eating Bananas, Median Two Arrays | E8: 20 | F8: NoSQL: DynamoDB, Cassandra, consistency models | G8: Design a KV store | H8: Master search on answer | I8: Solve Median Two Arrays without hints
A9: 6 | B9: Phase 3 | C9: Trees — BFS/DFS | D9: Invert Tree, Max Depth, Diameter, Level Order, Right Side View, Balanced Tree, Same Tree, Subtree | E9: 20 | F9: API Design: REST principles, pagination, versioning | G9: Design Twitter API | H9: Tree recursion mental model | I9: Implement iterative in-order traversal
A10: 7 | B10: Phase 3 | C10: BST + Trie | D10: LCA BST, Validate BST, Kth Smallest, Implement Trie, Add/Search Words, Word Search II | E10: 20 | F10: Message Queues: Kafka architecture, partitions, consumer groups | G10: Design notification system | H10: BST in-order = sorted; Trie prefix power | I10: Build Trie from scratch
A11: 8 | B11: Phase 3 | C11: Graphs — BFS/DFS | D11: Number of Islands, Clone Graph, Course Schedule I/II, Pacific Atlantic, Rotting Oranges, Word Ladder | E11: 25 | F11: Consistent Hashing + Sharding | G11: Design distributed cache with sharding | H11: DFS/BFS template mastery | I11: Topological sort both BFS & DFS
A12: 9 | B12: Phase 4 | C12: 1D DP | D12: Climbing Stairs, House Robber I/II, LIS, Coin Change, Word Break, Decode Ways, Palindromic Substrings, Max Product Subarray | E12: 25 | F12: Rate Limiting deep dive: token bucket, leaky bucket | G12: Design API rate limiter | H12: Define dp[i] precisely before coding | I12: Coin Change bottom-up and top-down
A13: 10 | B13: Phase 4 | C13: Backtracking + Greedy | D13: Subsets, Combination Sum I/II, Permutations, Palindrome Partitioning, N-Queens, Jump Game I/II, Gas Station | E13: 25 | F13: Blob Storage + CDN: S3, CloudFront, presigned URLs | G13: Design photo sharing (Instagram) | H13: Decision tree visualization | I13: N-Queens with pruning from memory
A14: 11 | B14: Phase 4 | C14: 2D DP | D14: Unique Paths, LCS, Edit Distance, Interleaving String, Burst Balloons, Best Time Buy/Sell III/IV, Distinct Subsequences | E14: 20 | F14: Search systems: Elasticsearch, inverted index, ranking | G14: Design type-ahead / autocomplete | H14: DP table transitions clarity | I14: Edit Distance with DP table drawn out
A15: 12 | B15: Phase 5 | C15: Heaps + Intervals | D15: K Closest Points, Task Scheduler, Find Median Stream, Merge K Sorted, Non-Overlapping Intervals, Meeting Rooms II | E15: 20 | F15: Real-time systems: WebSockets, long-polling, SSE | G15: Design chat application (WhatsApp) | H15: Heap invariants; interval sweep line | I15: Implement heap from scratch in Java
... A18: 15 | B18: Phase 7 | C18: Mock Interviews — Mixed | D18: FAANG-tagged problems: Amazon 40, Google 40, Meta 30, Microsoft 30 — timed 45-min sessions per problem | E18: 20 | F18: Full mock SDs: 60-min timed — Uber, Google Drive, Twitter | G18: Practice talking through design out loud | H18: Interview simulation under pressure | I18: Complete 2 full mock interviews
A19: 16 | B19: Phase 8 | C19: Final Sprint + Revision | D19: Re-solve all flagged retry problems; NeetCode 75 speed run; any weak areas | E19: 20+ | F19: Review all SD building blocks; practice trade-off discussions | G19: Behavioral + SD combos | H19: Confidence & polish | I19: Can you do any problem in under 25 min?

Sheet ⚡ Pattern Cheatsheet
A1: ⚡ PATTERN RECOGNITION CHEATSHEET — Identify the Pattern, Not Just the Problem
A3: Pattern | B3: Recognize When… | C3: Template / Approach | D3: Time Complexity | E3: Space Complexity | F3: Key Problems | G3: Gotchas
A4: Sliding Window (Variable) | B4: Max/min subarray satisfying a constraint; 'longest substring with...' | C4: Expand right pointer always; shrink left when constraint violated; track window state with map/int | D4: O(n) | E4: O(k) window size | F4: Min Window Substring, Longest Substring No Repeat, Fruit Into Baskets | G4: Define precisely when to shrink; avoid over-shrinking
A5: Two Pointers (Opposite Ends) | B5: Sorted array + pair/triplet sum; palindrome check; container problems | C5: lo=0, hi=n-1; move based on comparison to target; sort first if needed | D5: O(n log n) with sort | E5: O(1) | F5: 3Sum, Container With Water, Trapping Rain Water | G5: Sort destroys index — use values; watch duplicate skipping in 3Sum
A6: Fast & Slow Pointers | B6: Cycle detection, finding middle, kth from end | C6: slow=head, fast=head; slow moves 1, fast moves 2; check fast==slow for cycle | D6: O(n) | E6: O(1) | F6: Linked List Cycle, Find Duplicate Number, Happy Number | G6: For find duplicate: Floyd's cycle = detect, find entry = cycle start
A7: BFS (Level Order / Shortest Path) | B7: Shortest path in unweighted graph; level-by-level processing | C7: Queue with (node, dist/level); mark visited before enqueue not after dequeue | D7: O(V+E) | E7: O(V) | F7: Word Ladder, Rotting Oranges, Shortest Path in Binary Matrix | G7: Mark visited at enqueue time to avoid TLE
A8: DFS + Backtracking | B8: Generate all combinations/permutations/subsets; constraint satisfaction | C8: Choose → recurse → unchoose; prune early; track current path | D8: O(2^n) or O(n!) | E8: O(n) stack depth | F8: Subsets, Permutations, N-Queens, Sudoku Solver | G8: Draw decision tree first; add index param to avoid reuse
A9: Monotonic Stack (Decreasing) | B9: Next Greater Element; temperatures; histogram rectangle | C9: Maintain decreasing stack; pop when current > stack top; record answer at pop time | D9: O(n) | E9: O(n) | F9: Daily Temperatures, Largest Rect Histogram, Trapping Rain Water | G9: Know whether to store index vs value in stack
A10: Binary Search on Answer | B10: 'Minimum maximum' or 'Maximum minimum'; feasibility function exists | C10: lo=min_val, hi=max_val; binary search; write isValid(mid) function | D10: O(n log(range)) | E10: O(1) | F10: Koko Eating Bananas, Split Array Largest Sum, Capacity to Ship | G10: isValid() must be monotonic; think about lo/hi edge cases
A11: Top-K with Heap | B11: Kth largest/smallest; K most frequent; K closest | C11: Min-heap of size K for Kth largest; pop when size>K; heap top = answer | D11: O(n log k) | E11: O(k) | F11: Kth Largest, K Closest Points, Top K Frequent, Find Median Stream | G11: Min-heap for top-K largest (counter-intuitive); max-heap for Kth smallest
A12: 1D DP — Knapsack | B12: Include/exclude decision; optimal value with constraint | C12: dp[i] = max/min considering first i items; dp[i] = max(dp[i-1], dp[i-w]+val) | D12: O(n*W) | E12: O(n) or O(W) optimized | F12: 0/1 Knapsack, Coin Change, House Robber, Partition Equal Subset | G12: Traverse inner loop backwards for 0/1 (avoid reuse)
A13: 2D DP — Two Sequences | B13: LCS, Edit Distance, Interleaving — comparing two strings/arrays | C13: dp[i][j] = answer for s1[:i] and s2[:j]; fill row by row | D13: O(m*n) | E13: O(m*n) or O(n) optimized | F13: LCS, Edit Distance, Regex Match, Distinct Subsequences | G13: Define dp[0][j] and dp[i][0] base cases carefully
A14: Union-Find | B14: Connected components; dynamic connectivity; cycle in undirected graph | C14: find() with path compression; union() with rank; detect cycle if find(u)==find(v) before union | D14: O(α(n)) ≈ O(1) | E14: O(n) | F14: Redundant Connection, Number of Islands II, Accounts Merge | G14: Always implement both path compression AND union by rank
... A18: Interval Merge/Overlap | B18: Merging overlapping intervals; scheduling conflicts | C18: Sort by start; if curr.start <= prev.end → merge (update end); else add to result | D18: O(n log n) | E18: O(n) | F18: Merge Intervals, Non-Overlapping Intervals, Meeting Rooms II | G18: Sort by start for merge; sort by end for greedy scheduling

Sheet 🔁 Retry Tracker
A1: 🔁 SPACED REPETITION RETRY TRACKER — Revisit Hard Problems at 3 / 7 / 14 Days
A3: 🔍 FILTER TIPS: ▼ on Difficulty → filter Easy / Medium / Hard | ▼ on Topic → Text Filters → Contains → type e.g. 'Array' or 'DP'
A4: # | B4: LeetCode # | C4: Problem Name | D4: Topic | E4: Difficulty | F4: First Attempt Date | G4: Retry 1 Date (3 days) | H4: Retry 2 Date (7 days) | I4: Retry 3 Date (14 days) | K4: Cols B–E auto-fill from problems you mark 🔁 Retry in the Tracker (Excel 365 / Sheets). Fill the retry dates yourself.
A5: 1
A6: 2
A7: 3
A8: 4
A9: 5
A10: 6
A11: 7
A12: 8
A13: 9
A14: 10
A15: 11
A16: 12
... A104: 100

Sheet 🎯 Blind 75
A1: 🎯 BLIND 75 — Complete LeetCode Problem List with Patterns & Tracker | L1: 🎯 BLIND 75 — Complete LeetCode Problem List with Patterns & Tracker
A3: Curated by Krishna Dey | 75 problems covering all core interview patterns | Solve in order: Easy → Medium → Hard within each category
A4: 🔍 FILTER TIPS: ▼ on Difficulty → filter Easy / Medium / Hard | ▼ on Problem Types → Text Filters → Contains → type e.g. 'Array' or 'DP' | For multiple types: Custom Filter → Contains 'Array' AND/OR Contains 'BFS'
A5: # | B5: Category | C5: LC # | D5: Problem Title | E5: Difficulty | F5: Key Pattern / Insight | G5: LeetCode URL | H5: Premium? | I5: ✅ Status (auto) | J5: Date Solved | K5: Notes / Your Insight | L5: Problem Types | M5: How to Solve | N5: Time Complexity | O5: Space Complexity
A6: ARRAY — 10 problems
A7: 1 | B7: Array | C7: 1 | D7: Two Sum | E7: Easy | F7: HashMap complement lookup | G7: =HYPERLINK("https://leetcode.com/problems/two-sum/","https://leetcode.com/problems/two-sum/") -> https://leetcode.com/problems/two-sum/ | I7: =IFERROR(VLOOKUP(C7,'📊 Problem Tracker'!$B$4:$F$1200,5,FALSE()),"") -> 0 | L7: Array, Hashing | M7: HashMap (One-Pass): Store each number's index in a map. For each element, check if (target - num) exists before inserting. | N7: O(n) | O7: O(n)
A8: 2 | B8: Array | C8: 121 | D8: Best Time to Buy and Sell Stock | E8: Easy | F8: Track running min; max profit at each step | G8: =HYPERLINK("https://leetcode.com/problems/best-time-to-buy-and-sell-stock/","https://leetcode.com/problems/best-time-to-buy-and-sell-stock/") -> https://leetcode.com/problems/best-time-to-buy-and-sell-stock/ | I8: =IFERROR(VLOOKUP(C8,'📊 Problem Tracker'!$B$4:$F$1200,5,FALSE()),"") -> 0 | L8: Array, Greedy | M8: Single Pass - Track Min Price: Track the lowest price so far and update max profit using current price minus min price. | N8: O(n) | O8: O(1)
A9: 3 | B9: Array | C9: 217 | D9: Contains Duplicate | E9: Easy | F9: HashSet membership | G9: =HYPERLINK("https://leetcode.com/problems/contains-duplicate/","https://leetcode.com/problems/contains-duplicate/") -> https://leetcode.com/problems/contains-duplicate/ | I9: =IFERROR(VLOOKUP(C9,'📊 Problem Tracker'!$B$4:$F$1200,5,FALSE()),"") -> 0 | L9: Array, Hashing | M9: HashSet Membership Check: Insert each value into a set and return true if it already exists. | N9: O(n) | O9: O(n)
A10: 4 | B10: Array | C10: 238 | D10: Product of Array Except Self | E10: Medium | F10: Prefix & suffix product passes; no division | G10: =HYPERLINK("https://leetcode.com/problems/product-of-array-except-self/","https://leetcode.com/problems/product-of-array-except-self/") -> https://leetcode.com/problems/product-of-array-except-self/ | I10: =IFERROR(VLOOKUP(C10,'📊 Problem Tracker'!$B$4:$F$1200,5,FALSE()),"") -> 0 | L10: Array, Prefix Sum | M10: Prefix and Suffix Products: Compute product of all elements left of each index, then multiply by running suffix from the right. | N10: O(n) | O10: O(1) excluding output
A11: 5 | B11: Array | C11: 53 | D11: Maximum Subarray | E11: Medium | F11: Kadane's algorithm — reset when sum < 0 | G11: =HYPERLINK("https://leetcode.com/problems/maximum-subarray/","https://leetcode.com/problems/maximum-subarray/") -> https://leetcode.com/problems/maximum-subarray/ | I11: =IFERROR(VLOOKUP(C11,'📊 Problem Tracker'!$B$4:$F$1200,5,FALSE()),"") -> 0 | L11: Array, DP | M11: Kadane's Algorithm: Track best subarray ending at current index and global best; restart when current value is better. | N11: O(n) | O11: O(1)
A12: 6 | B12: Array | C12: 152 | D12: Maximum Product Subarray | E12: Medium | F12: Track max & min (negatives flip sign) | G12: =HYPERLINK("https://leetcode.com/problems/maximum-product-subarray/","https://leetcode.com/problems/maximum-product-subarray/") -> https://leetcode.com/problems/maximum-product-subarray/ | I12: =IFERROR(VLOOKUP(C12,'📊 Problem Tracker'!$B$4:$F$1200,5,FALSE()),"") -> 0 | L12: Array, DP | M12: DP - Track Max and Min Product: Track both max and min product ending here because negatives can flip them. | N12: O(n) | O12: O(1)
A13: 7 | B13: Array | C13: 153 | D13: Find Minimum in Rotated Sorted Array | E13: Medium | F13: Binary search — which half is sorted? | G13: =HYPERLINK("https://leetcode.com/problems/find-minimum-in-rotated-sorted-array/","https://leetcode.com/problems/find-minimum-in-rotated-sorted-array/") -> https://leetcode.com/problems/find-minimum-in-rotated-sorted-array/ | I13: =IFERROR(VLOOKUP(C13,'📊 Problem Tracker'!$B$4:$F$1200,5,FALSE()),"") -> 0 | L13: Array, Binary Search | M13: Binary Search - Minimum in Rotated: Compare mid with right boundary to decide which side contains the minimum. | N13: O(log n) | O13: O(1)
A14: 8 | B14: Array | C14: 33 | D14: Search in Rotated Sorted Array | E14: Medium | F14: Binary search with rotation pivot logic | G14: =HYPERLINK("https://leetcode.com/problems/search-in-rotated-sorted-array/","https://leetcode.com/problems/search-in-rotated-sorted-array/") -> https://leetcode.com/problems/search-in-rotated-sorted-array/ | I14: =IFERROR(VLOOKUP(C14,'📊 Problem Tracker'!$B$4:$F$1200,5,FALSE()),"") -> 0 | L14: Array, Binary Search | M14: Binary Search - Identify Sorted Half: At each mid, determine which half is sorted and narrow search to the half that can contain target. | N14: O(log n) | O14: O(1)
